[2022-08-24 00:04:24,903] {taskinstance.py:1179} INFO - Dependencies all met for <TaskInstance: raizen_lab_01.carga_arquivo manual__2022-08-24T00:03:21.416479+00:00 [queued]>
[2022-08-24 00:04:24,913] {taskinstance.py:1179} INFO - Dependencies all met for <TaskInstance: raizen_lab_01.carga_arquivo manual__2022-08-24T00:03:21.416479+00:00 [queued]>
[2022-08-24 00:04:24,914] {taskinstance.py:1376} INFO - 
--------------------------------------------------------------------------------
[2022-08-24 00:04:24,915] {taskinstance.py:1377} INFO - Starting attempt 2 of 2
[2022-08-24 00:04:24,916] {taskinstance.py:1378} INFO - 
--------------------------------------------------------------------------------
[2022-08-24 00:04:24,933] {taskinstance.py:1397} INFO - Executing <Task(PythonOperator): carga_arquivo> on 2022-08-24 00:03:21.416479+00:00
[2022-08-24 00:04:24,942] {standard_task_runner.py:52} INFO - Started process 124 to run task
[2022-08-24 00:04:24,947] {standard_task_runner.py:79} INFO - Running: ['***', 'tasks', 'run', 'raizen_lab_01', 'carga_arquivo', 'manual__2022-08-24T00:03:21.416479+00:00', '--job-id', '9585', '--raw', '--subdir', 'DAGS_FOLDER/raizen_lab_01.py', '--cfg-path', '/tmp/tmpupmvvw0z', '--error-file', '/tmp/tmpni8v8bzj']
[2022-08-24 00:04:24,949] {standard_task_runner.py:80} INFO - Job 9585: Subtask carga_arquivo
[2022-08-24 00:04:25,051] {task_command.py:371} INFO - Running <TaskInstance: raizen_lab_01.carga_arquivo manual__2022-08-24T00:03:21.416479+00:00 [running]> on host 25dd15f8d678
[2022-08-24 00:04:25,154] {taskinstance.py:1591} INFO - Exporting the following env vars:
AIRFLOW_CTX_DAG_OWNER=admin
AIRFLOW_CTX_DAG_ID=raizen_lab_01
AIRFLOW_CTX_TASK_ID=carga_arquivo
AIRFLOW_CTX_EXECUTION_DATE=2022-08-24T00:03:21.416479+00:00
AIRFLOW_CTX_TRY_NUMBER=2
AIRFLOW_CTX_DAG_RUN_ID=manual__2022-08-24T00:03:21.416479+00:00
[2022-08-24 00:04:26,147] {taskinstance.py:1909} ERROR - Task failed with exception
Traceback (most recent call last):
  File "/home/airflow/.local/lib/python3.7/site-packages/MySQLdb/cursors.py", line 201, in execute
    query = query % args
TypeError: not all arguments converted during bytes formatting

During handling of the above exception, another exception occurred:

Traceback (most recent call last):
  File "/home/airflow/.local/lib/python3.7/site-packages/pandas/io/sql.py", line 2056, in execute
    cur.execute(*args, **kwargs)
  File "/home/airflow/.local/lib/python3.7/site-packages/MySQLdb/cursors.py", line 203, in execute
    raise ProgrammingError(str(m))
MySQLdb.ProgrammingError: not all arguments converted during bytes formatting

The above exception was the direct cause of the following exception:

Traceback (most recent call last):
  File "/home/airflow/.local/lib/python3.7/site-packages/airflow/operators/python.py", line 171, in execute
    return_value = self.execute_callable()
  File "/home/airflow/.local/lib/python3.7/site-packages/airflow/operators/python.py", line 189, in execute_callable
    return self.python_callable(*self.op_args, **self.op_kwargs)
  File "/opt/airflow/dags/raizen_lab_01.py", line 36, in carga_arquivo
    df_sheet_index.to_sql(con=con, name='table_name_for_df', if_exists="replace", index=False)
  File "/home/airflow/.local/lib/python3.7/site-packages/pandas/core/generic.py", line 2882, in to_sql
    method=method,
  File "/home/airflow/.local/lib/python3.7/site-packages/pandas/io/sql.py", line 728, in to_sql
    **engine_kwargs,
  File "/home/airflow/.local/lib/python3.7/site-packages/pandas/io/sql.py", line 2225, in to_sql
    table.create()
  File "/home/airflow/.local/lib/python3.7/site-packages/pandas/io/sql.py", line 856, in create
    if self.exists():
  File "/home/airflow/.local/lib/python3.7/site-packages/pandas/io/sql.py", line 840, in exists
    return self.pd_sql.has_table(self.name, self.schema)
  File "/home/airflow/.local/lib/python3.7/site-packages/pandas/io/sql.py", line 2236, in has_table
    return len(self.execute(query, [name]).fetchall()) > 0
  File "/home/airflow/.local/lib/python3.7/site-packages/pandas/io/sql.py", line 2068, in execute
    raise ex from exc
pandas.io.sql.DatabaseError: Execution failed on sql 'SELECT name FROM sqlite_master WHERE type='table' AND name=?;': not all arguments converted during bytes formatting
[2022-08-24 00:04:26,168] {taskinstance.py:1420} INFO - Marking task as FAILED. dag_id=raizen_lab_01, task_id=carga_arquivo, execution_date=20220824T000321, start_date=20220824T000424, end_date=20220824T000426
[2022-08-24 00:04:26,187] {standard_task_runner.py:97} ERROR - Failed to execute job 9585 for task carga_arquivo (Execution failed on sql 'SELECT name FROM sqlite_master WHERE type='table' AND name=?;': not all arguments converted during bytes formatting; 124)
[2022-08-24 00:04:26,206] {local_task_job.py:156} INFO - Task exited with return code 1
[2022-08-24 00:04:26,349] {local_task_job.py:273} INFO - 0 downstream tasks scheduled from follow-on schedule check
