[2022-08-23 14:22:43,222] {taskinstance.py:1179} INFO - Dependencies all met for <TaskInstance: raizen_lab_01.create_pet_table scheduled__2022-01-03T05:00:00+00:00 [queued]>
[2022-08-23 14:22:43,245] {taskinstance.py:1179} INFO - Dependencies all met for <TaskInstance: raizen_lab_01.create_pet_table scheduled__2022-01-03T05:00:00+00:00 [queued]>
[2022-08-23 14:22:43,245] {taskinstance.py:1376} INFO - 
--------------------------------------------------------------------------------
[2022-08-23 14:22:43,247] {taskinstance.py:1377} INFO - Starting attempt 1 of 2
[2022-08-23 14:22:43,252] {taskinstance.py:1378} INFO - 
--------------------------------------------------------------------------------
[2022-08-23 14:22:43,293] {taskinstance.py:1397} INFO - Executing <Task(PostgresOperator): create_pet_table> on 2022-01-03 05:00:00+00:00
[2022-08-23 14:22:43,307] {standard_task_runner.py:52} INFO - Started process 107 to run task
[2022-08-23 14:22:43,313] {standard_task_runner.py:79} INFO - Running: ['***', 'tasks', 'run', 'raizen_lab_01', 'create_pet_table', 'scheduled__2022-01-03T05:00:00+00:00', '--job-id', '7842', '--raw', '--subdir', 'DAGS_FOLDER/raizen_lab_01.py', '--cfg-path', '/tmp/tmpj9_e91i4', '--error-file', '/tmp/tmpqdfdvb90']
[2022-08-23 14:22:43,317] {standard_task_runner.py:80} INFO - Job 7842: Subtask create_pet_table
[2022-08-23 14:22:43,531] {task_command.py:371} INFO - Running <TaskInstance: raizen_lab_01.create_pet_table scheduled__2022-01-03T05:00:00+00:00 [running]> on host 02d9cdd4a2f7
[2022-08-23 14:22:43,838] {taskinstance.py:1591} INFO - Exporting the following env vars:
AIRFLOW_CTX_DAG_OWNER=admin
AIRFLOW_CTX_DAG_ID=raizen_lab_01
AIRFLOW_CTX_TASK_ID=create_pet_table
AIRFLOW_CTX_EXECUTION_DATE=2022-01-03T05:00:00+00:00
AIRFLOW_CTX_TRY_NUMBER=1
AIRFLOW_CTX_DAG_RUN_ID=scheduled__2022-01-03T05:00:00+00:00
[2022-08-23 14:22:43,917] {taskinstance.py:1909} ERROR - Task failed with exception
Traceback (most recent call last):
  File "/home/airflow/.local/lib/python3.7/site-packages/airflow/providers/postgres/operators/postgres.py", line 92, in execute
    self.hook.run(self.sql, self.autocommit, parameters=self.parameters)
  File "/home/airflow/.local/lib/python3.7/site-packages/airflow/hooks/dbapi.py", line 204, in run
    with closing(self.get_conn()) as conn:
  File "/home/airflow/.local/lib/python3.7/site-packages/airflow/providers/postgres/hooks/postgres.py", line 86, in get_conn
    conn = deepcopy(self.connection or self.get_connection(conn_id))
  File "/home/airflow/.local/lib/python3.7/site-packages/airflow/hooks/base.py", line 67, in get_connection
    conn = Connection.get_connection_from_secrets(conn_id)
  File "/home/airflow/.local/lib/python3.7/site-packages/airflow/models/connection.py", line 430, in get_connection_from_secrets
    raise AirflowNotFoundException(f"The conn_id `{conn_id}` isn't defined")
airflow.exceptions.AirflowNotFoundException: The conn_id `postgres_default` isn't defined
[2022-08-23 14:22:43,945] {taskinstance.py:1420} INFO - Marking task as UP_FOR_RETRY. dag_id=raizen_lab_01, task_id=create_pet_table, execution_date=20220103T050000, start_date=20220823T142243, end_date=20220823T142243
[2022-08-23 14:22:44,034] {standard_task_runner.py:97} ERROR - Failed to execute job 7842 for task create_pet_table (The conn_id `postgres_default` isn't defined; 107)
[2022-08-23 14:22:44,074] {local_task_job.py:156} INFO - Task exited with return code 1
[2022-08-23 14:22:44,119] {local_task_job.py:273} INFO - 0 downstream tasks scheduled from follow-on schedule check
