[2022-08-24 01:56:30,905] {taskinstance.py:1179} INFO - Dependencies all met for <TaskInstance: raizen_lab_01.carga_arquivo manual__2022-08-24T01:56:29.152624+00:00 [queued]>
[2022-08-24 01:56:30,923] {taskinstance.py:1179} INFO - Dependencies all met for <TaskInstance: raizen_lab_01.carga_arquivo manual__2022-08-24T01:56:29.152624+00:00 [queued]>
[2022-08-24 01:56:30,924] {taskinstance.py:1376} INFO - 
--------------------------------------------------------------------------------
[2022-08-24 01:56:30,924] {taskinstance.py:1377} INFO - Starting attempt 1 of 2
[2022-08-24 01:56:30,925] {taskinstance.py:1378} INFO - 
--------------------------------------------------------------------------------
[2022-08-24 01:56:30,947] {taskinstance.py:1397} INFO - Executing <Task(PythonOperator): carga_arquivo> on 2022-08-24 01:56:29.152624+00:00
[2022-08-24 01:56:30,954] {standard_task_runner.py:52} INFO - Started process 74 to run task
[2022-08-24 01:56:30,961] {standard_task_runner.py:79} INFO - Running: ['***', 'tasks', 'run', 'raizen_lab_01', 'carga_arquivo', 'manual__2022-08-24T01:56:29.152624+00:00', '--job-id', '9640', '--raw', '--subdir', 'DAGS_FOLDER/raizen_lab_01.py', '--cfg-path', '/tmp/tmpzdum2epe', '--error-file', '/tmp/tmpfkt92uix']
[2022-08-24 01:56:30,963] {standard_task_runner.py:80} INFO - Job 9640: Subtask carga_arquivo
[2022-08-24 01:56:31,098] {task_command.py:371} INFO - Running <TaskInstance: raizen_lab_01.carga_arquivo manual__2022-08-24T01:56:29.152624+00:00 [running]> on host b8d797566373
[2022-08-24 01:56:31,259] {taskinstance.py:1591} INFO - Exporting the following env vars:
AIRFLOW_CTX_DAG_OWNER=admin
AIRFLOW_CTX_DAG_ID=raizen_lab_01
AIRFLOW_CTX_TASK_ID=carga_arquivo
AIRFLOW_CTX_EXECUTION_DATE=2022-08-24T01:56:29.152624+00:00
AIRFLOW_CTX_TRY_NUMBER=1
AIRFLOW_CTX_DAG_RUN_ID=manual__2022-08-24T01:56:29.152624+00:00
[2022-08-24 01:56:32,872] {logging_mixin.py:115} INFO -        ANO
0     2000
1     2000
2     2000
3     2000
4     2000
...    ...
4531  2020
4532  2020
4533  2020
4534  2020
4535  2020

[4536 rows x 1 columns]
[2022-08-24 01:56:32,947] {taskinstance.py:1909} ERROR - Task failed with exception
Traceback (most recent call last):
  File "/home/airflow/.local/lib/python3.7/site-packages/airflow/operators/python.py", line 171, in execute
    return_value = self.execute_callable()
  File "/home/airflow/.local/lib/python3.7/site-packages/airflow/operators/python.py", line 189, in execute_callable
    return self.python_callable(*self.op_args, **self.op_kwargs)
  File "/opt/airflow/dags/raizen_lab_01.py", line 46, in carga_arquivo
    df.to_sql('modelo', engine, index=False)
  File "/home/airflow/.local/lib/python3.7/site-packages/pandas/core/generic.py", line 2882, in to_sql
    method=method,
  File "/home/airflow/.local/lib/python3.7/site-packages/pandas/io/sql.py", line 728, in to_sql
    **engine_kwargs,
  File "/home/airflow/.local/lib/python3.7/site-packages/pandas/io/sql.py", line 1758, in to_sql
    dtype=dtype,
  File "/home/airflow/.local/lib/python3.7/site-packages/pandas/io/sql.py", line 1650, in prep_table
    table.create()
  File "/home/airflow/.local/lib/python3.7/site-packages/pandas/io/sql.py", line 858, in create
    raise ValueError(f"Table '{self.name}' already exists.")
ValueError: Table 'modelo' already exists.
[2022-08-24 01:56:32,987] {taskinstance.py:1420} INFO - Marking task as UP_FOR_RETRY. dag_id=raizen_lab_01, task_id=carga_arquivo, execution_date=20220824T015629, start_date=20220824T015630, end_date=20220824T015632
[2022-08-24 01:56:33,024] {standard_task_runner.py:97} ERROR - Failed to execute job 9640 for task carga_arquivo (Table 'modelo' already exists.; 74)
[2022-08-24 01:56:33,062] {local_task_job.py:156} INFO - Task exited with return code 1
[2022-08-24 01:56:33,155] {local_task_job.py:273} INFO - 0 downstream tasks scheduled from follow-on schedule check
