[2022-08-23 23:46:28,962] {taskinstance.py:1179} INFO - Dependencies all met for <TaskInstance: raizen_lab_01.carga_arquivo manual__2022-08-23T23:45:23.928517+00:00 [queued]>
[2022-08-23 23:46:28,971] {taskinstance.py:1179} INFO - Dependencies all met for <TaskInstance: raizen_lab_01.carga_arquivo manual__2022-08-23T23:45:23.928517+00:00 [queued]>
[2022-08-23 23:46:28,972] {taskinstance.py:1376} INFO - 
--------------------------------------------------------------------------------
[2022-08-23 23:46:28,972] {taskinstance.py:1377} INFO - Starting attempt 2 of 2
[2022-08-23 23:46:28,973] {taskinstance.py:1378} INFO - 
--------------------------------------------------------------------------------
[2022-08-23 23:46:28,992] {taskinstance.py:1397} INFO - Executing <Task(PythonOperator): carga_arquivo> on 2022-08-23 23:45:23.928517+00:00
[2022-08-23 23:46:28,998] {standard_task_runner.py:52} INFO - Started process 74 to run task
[2022-08-23 23:46:29,001] {standard_task_runner.py:79} INFO - Running: ['***', 'tasks', 'run', 'raizen_lab_01', 'carga_arquivo', 'manual__2022-08-23T23:45:23.928517+00:00', '--job-id', '9555', '--raw', '--subdir', 'DAGS_FOLDER/raizen_lab_01.py', '--cfg-path', '/tmp/tmpofrgymzz', '--error-file', '/tmp/tmpxmmwuddb']
[2022-08-23 23:46:29,003] {standard_task_runner.py:80} INFO - Job 9555: Subtask carga_arquivo
[2022-08-23 23:46:29,073] {task_command.py:371} INFO - Running <TaskInstance: raizen_lab_01.carga_arquivo manual__2022-08-23T23:45:23.928517+00:00 [running]> on host 25dd15f8d678
[2022-08-23 23:46:29,144] {taskinstance.py:1591} INFO - Exporting the following env vars:
AIRFLOW_CTX_DAG_OWNER=admin
AIRFLOW_CTX_DAG_ID=raizen_lab_01
AIRFLOW_CTX_TASK_ID=carga_arquivo
AIRFLOW_CTX_EXECUTION_DATE=2022-08-23T23:45:23.928517+00:00
AIRFLOW_CTX_TRY_NUMBER=2
AIRFLOW_CTX_DAG_RUN_ID=manual__2022-08-23T23:45:23.928517+00:00
[2022-08-23 23:46:29,955] {taskinstance.py:1909} ERROR - Task failed with exception
Traceback (most recent call last):
  File "/home/airflow/.local/lib/python3.7/site-packages/airflow/operators/python.py", line 171, in execute
    return_value = self.execute_callable()
  File "/home/airflow/.local/lib/python3.7/site-packages/airflow/operators/python.py", line 189, in execute_callable
    return self.python_callable(*self.op_args, **self.op_kwargs)
  File "/opt/airflow/dags/raizen_lab_01.py", line 33, in carga_arquivo
    df1  = df['COMBUSTÍVEL':'ANO']
  File "/home/airflow/.local/lib/python3.7/site-packages/pandas/core/frame.py", line 3430, in __getitem__
    indexer = convert_to_index_sliceable(self, key)
  File "/home/airflow/.local/lib/python3.7/site-packages/pandas/core/indexing.py", line 2329, in convert_to_index_sliceable
    return idx._convert_slice_indexer(key, kind="getitem")
  File "/home/airflow/.local/lib/python3.7/site-packages/pandas/core/indexes/numeric.py", line 244, in _convert_slice_indexer
    return super()._convert_slice_indexer(key, kind=kind)
  File "/home/airflow/.local/lib/python3.7/site-packages/pandas/core/indexes/base.py", line 3719, in _convert_slice_indexer
    self._validate_indexer("slice", key.start, "getitem")
  File "/home/airflow/.local/lib/python3.7/site-packages/pandas/core/indexes/base.py", line 5719, in _validate_indexer
    raise self._invalid_indexer(form, key)
TypeError: cannot do slice indexing on RangeIndex with these indexers [COMBUSTÍVEL] of type str
[2022-08-23 23:46:29,977] {taskinstance.py:1420} INFO - Marking task as FAILED. dag_id=raizen_lab_01, task_id=carga_arquivo, execution_date=20220823T234523, start_date=20220823T234628, end_date=20220823T234629
[2022-08-23 23:46:29,992] {standard_task_runner.py:97} ERROR - Failed to execute job 9555 for task carga_arquivo (cannot do slice indexing on RangeIndex with these indexers [COMBUSTÍVEL] of type str; 74)
[2022-08-23 23:46:30,018] {local_task_job.py:156} INFO - Task exited with return code 1
[2022-08-23 23:46:30,059] {local_task_job.py:273} INFO - 0 downstream tasks scheduled from follow-on schedule check
