[2022-08-23 16:16:05,237] {taskinstance.py:1179} INFO - Dependencies all met for <TaskInstance: raizen_lab_01.conecta_no_mysql scheduled__2022-01-06T03:00:00+00:00 [queued]>
[2022-08-23 16:16:05,254] {taskinstance.py:1179} INFO - Dependencies all met for <TaskInstance: raizen_lab_01.conecta_no_mysql scheduled__2022-01-06T03:00:00+00:00 [queued]>
[2022-08-23 16:16:05,255] {taskinstance.py:1376} INFO - 
--------------------------------------------------------------------------------
[2022-08-23 16:16:05,255] {taskinstance.py:1377} INFO - Starting attempt 1 of 2
[2022-08-23 16:16:05,256] {taskinstance.py:1378} INFO - 
--------------------------------------------------------------------------------
[2022-08-23 16:16:05,278] {taskinstance.py:1397} INFO - Executing <Task(PythonOperator): conecta_no_mysql> on 2022-01-06 03:00:00+00:00
[2022-08-23 16:16:05,287] {standard_task_runner.py:52} INFO - Started process 806 to run task
[2022-08-23 16:16:05,293] {standard_task_runner.py:79} INFO - Running: ['***', 'tasks', 'run', 'raizen_lab_01', 'conecta_no_mysql', 'scheduled__2022-01-06T03:00:00+00:00', '--job-id', '8128', '--raw', '--subdir', 'DAGS_FOLDER/raizen_lab_01.py', '--cfg-path', '/tmp/tmph3b7q931', '--error-file', '/tmp/tmpjthtwyvu']
[2022-08-23 16:16:05,295] {standard_task_runner.py:80} INFO - Job 8128: Subtask conecta_no_mysql
[2022-08-23 16:16:05,412] {task_command.py:371} INFO - Running <TaskInstance: raizen_lab_01.conecta_no_mysql scheduled__2022-01-06T03:00:00+00:00 [running]> on host 8790b68fb5bc
[2022-08-23 16:16:05,516] {taskinstance.py:1591} INFO - Exporting the following env vars:
AIRFLOW_CTX_DAG_OWNER=admin
AIRFLOW_CTX_DAG_ID=raizen_lab_01
AIRFLOW_CTX_TASK_ID=conecta_no_mysql
AIRFLOW_CTX_EXECUTION_DATE=2022-01-06T03:00:00+00:00
AIRFLOW_CTX_TRY_NUMBER=1
AIRFLOW_CTX_DAG_RUN_ID=scheduled__2022-01-06T03:00:00+00:00
[2022-08-23 16:16:05,548] {taskinstance.py:1909} ERROR - Task failed with exception
Traceback (most recent call last):
  File "/home/airflow/.local/lib/python3.7/site-packages/airflow/operators/python.py", line 171, in execute
    return_value = self.execute_callable()
  File "/home/airflow/.local/lib/python3.7/site-packages/airflow/operators/python.py", line 189, in execute_callable
    return self.python_callable(*self.op_args, **self.op_kwargs)
  File "/opt/airflow/dags/raizen_lab_01.py", line 35, in conecta_no_mysql
    con.select_db('banco de dados')
MySQLdb.OperationalError: (1044, "Access denied for user 'user'@'%' to database 'banco de dados'")
[2022-08-23 16:16:05,567] {taskinstance.py:1420} INFO - Marking task as UP_FOR_RETRY. dag_id=raizen_lab_01, task_id=conecta_no_mysql, execution_date=20220106T030000, start_date=20220823T161605, end_date=20220823T161605
[2022-08-23 16:16:05,589] {standard_task_runner.py:97} ERROR - Failed to execute job 8128 for task conecta_no_mysql ((1044, "Access denied for user 'user'@'%' to database 'banco de dados'"); 806)
[2022-08-23 16:16:05,625] {local_task_job.py:156} INFO - Task exited with return code 1
[2022-08-23 16:16:05,683] {local_task_job.py:273} INFO - 0 downstream tasks scheduled from follow-on schedule check
