[2022-08-23 23:42:52,211] {taskinstance.py:1179} INFO - Dependencies all met for <TaskInstance: raizen_lab_01.carga_arquivo manual__2022-08-23T23:42:51.013101+00:00 [queued]>
[2022-08-23 23:42:52,219] {taskinstance.py:1179} INFO - Dependencies all met for <TaskInstance: raizen_lab_01.carga_arquivo manual__2022-08-23T23:42:51.013101+00:00 [queued]>
[2022-08-23 23:42:52,219] {taskinstance.py:1376} INFO - 
--------------------------------------------------------------------------------
[2022-08-23 23:42:52,220] {taskinstance.py:1377} INFO - Starting attempt 1 of 2
[2022-08-23 23:42:52,220] {taskinstance.py:1378} INFO - 
--------------------------------------------------------------------------------
[2022-08-23 23:42:52,236] {taskinstance.py:1397} INFO - Executing <Task(PythonOperator): carga_arquivo> on 2022-08-23 23:42:51.013101+00:00
[2022-08-23 23:42:52,241] {standard_task_runner.py:52} INFO - Started process 74 to run task
[2022-08-23 23:42:52,244] {standard_task_runner.py:79} INFO - Running: ['***', 'tasks', 'run', 'raizen_lab_01', 'carga_arquivo', 'manual__2022-08-23T23:42:51.013101+00:00', '--job-id', '9535', '--raw', '--subdir', 'DAGS_FOLDER/raizen_lab_01.py', '--cfg-path', '/tmp/tmp93pn12mv', '--error-file', '/tmp/tmpn_hfc0y5']
[2022-08-23 23:42:52,245] {standard_task_runner.py:80} INFO - Job 9535: Subtask carga_arquivo
[2022-08-23 23:42:52,314] {task_command.py:371} INFO - Running <TaskInstance: raizen_lab_01.carga_arquivo manual__2022-08-23T23:42:51.013101+00:00 [running]> on host 25dd15f8d678
[2022-08-23 23:42:52,390] {taskinstance.py:1591} INFO - Exporting the following env vars:
AIRFLOW_CTX_DAG_OWNER=admin
AIRFLOW_CTX_DAG_ID=raizen_lab_01
AIRFLOW_CTX_TASK_ID=carga_arquivo
AIRFLOW_CTX_EXECUTION_DATE=2022-08-23T23:42:51.013101+00:00
AIRFLOW_CTX_TRY_NUMBER=1
AIRFLOW_CTX_DAG_RUN_ID=manual__2022-08-23T23:42:51.013101+00:00
[2022-08-23 23:42:53,191] {taskinstance.py:1909} ERROR - Task failed with exception
Traceback (most recent call last):
  File "/home/airflow/.local/lib/python3.7/site-packages/pandas/core/indexes/base.py", line 3361, in get_loc
    return self._engine.get_loc(casted_key)
  File "pandas/_libs/index.pyx", line 76, in pandas._libs.index.IndexEngine.get_loc
  File "pandas/_libs/index.pyx", line 108, in pandas._libs.index.IndexEngine.get_loc
  File "pandas/_libs/hashtable_class_helper.pxi", line 5198, in pandas._libs.hashtable.PyObjectHashTable.get_item
  File "pandas/_libs/hashtable_class_helper.pxi", line 5206, in pandas._libs.hashtable.PyObjectHashTable.get_item
KeyError: ('COMBUSTÍVEL', 'ANO')

The above exception was the direct cause of the following exception:

Traceback (most recent call last):
  File "/home/airflow/.local/lib/python3.7/site-packages/airflow/operators/python.py", line 171, in execute
    return_value = self.execute_callable()
  File "/home/airflow/.local/lib/python3.7/site-packages/airflow/operators/python.py", line 189, in execute_callable
    return self.python_callable(*self.op_args, **self.op_kwargs)
  File "/opt/airflow/dags/raizen_lab_01.py", line 33, in carga_arquivo
    print(df['COMBUSTÍVEL','ANO'])
  File "/home/airflow/.local/lib/python3.7/site-packages/pandas/core/frame.py", line 3458, in __getitem__
    indexer = self.columns.get_loc(key)
  File "/home/airflow/.local/lib/python3.7/site-packages/pandas/core/indexes/base.py", line 3363, in get_loc
    raise KeyError(key) from err
KeyError: ('COMBUSTÍVEL', 'ANO')
[2022-08-23 23:42:53,233] {taskinstance.py:1420} INFO - Marking task as UP_FOR_RETRY. dag_id=raizen_lab_01, task_id=carga_arquivo, execution_date=20220823T234251, start_date=20220823T234252, end_date=20220823T234253
[2022-08-23 23:42:53,250] {standard_task_runner.py:97} ERROR - Failed to execute job 9535 for task carga_arquivo (('COMBUSTÍVEL', 'ANO'); 74)
[2022-08-23 23:42:53,261] {local_task_job.py:156} INFO - Task exited with return code 1
[2022-08-23 23:42:53,298] {local_task_job.py:273} INFO - 0 downstream tasks scheduled from follow-on schedule check
