[2022-08-23 17:34:29,082] {taskinstance.py:1179} INFO - Dependencies all met for <TaskInstance: raizen_lab_01.conecta_no_mysql scheduled__2022-01-14T10:00:00+00:00 [queued]>
[2022-08-23 17:34:29,093] {taskinstance.py:1179} INFO - Dependencies all met for <TaskInstance: raizen_lab_01.conecta_no_mysql scheduled__2022-01-14T10:00:00+00:00 [queued]>
[2022-08-23 17:34:29,094] {taskinstance.py:1376} INFO - 
--------------------------------------------------------------------------------
[2022-08-23 17:34:29,095] {taskinstance.py:1377} INFO - Starting attempt 1 of 2
[2022-08-23 17:34:29,095] {taskinstance.py:1378} INFO - 
--------------------------------------------------------------------------------
[2022-08-23 17:34:29,112] {taskinstance.py:1397} INFO - Executing <Task(PythonOperator): conecta_no_mysql> on 2022-01-14 10:00:00+00:00
[2022-08-23 17:34:29,120] {standard_task_runner.py:52} INFO - Started process 172 to run task
[2022-08-23 17:34:29,123] {standard_task_runner.py:79} INFO - Running: ['***', 'tasks', 'run', 'raizen_lab_01', 'conecta_no_mysql', 'scheduled__2022-01-14T10:00:00+00:00', '--job-id', '8595', '--raw', '--subdir', 'DAGS_FOLDER/raizen_lab_01.py', '--cfg-path', '/tmp/tmpz889xsxk', '--error-file', '/tmp/tmp420j02x3']
[2022-08-23 17:34:29,125] {standard_task_runner.py:80} INFO - Job 8595: Subtask conecta_no_mysql
[2022-08-23 17:34:29,191] {task_command.py:371} INFO - Running <TaskInstance: raizen_lab_01.conecta_no_mysql scheduled__2022-01-14T10:00:00+00:00 [running]> on host 8d054a683dd2
[2022-08-23 17:34:29,265] {taskinstance.py:1591} INFO - Exporting the following env vars:
AIRFLOW_CTX_DAG_OWNER=admin
AIRFLOW_CTX_DAG_ID=raizen_lab_01
AIRFLOW_CTX_TASK_ID=conecta_no_mysql
AIRFLOW_CTX_EXECUTION_DATE=2022-01-14T10:00:00+00:00
AIRFLOW_CTX_TRY_NUMBER=1
AIRFLOW_CTX_DAG_RUN_ID=scheduled__2022-01-14T10:00:00+00:00
[2022-08-23 17:34:32,421] {taskinstance.py:1909} ERROR - Task failed with exception
Traceback (most recent call last):
  File "/home/airflow/.local/lib/python3.7/site-packages/airflow/operators/python.py", line 171, in execute
    return_value = self.execute_callable()
  File "/home/airflow/.local/lib/python3.7/site-packages/airflow/operators/python.py", line 189, in execute_callable
    return self.python_callable(*self.op_args, **self.op_kwargs)
  File "/opt/airflow/dags/raizen_lab_01.py", line 35, in conecta_no_mysql
    con = MySQLdb.connect(host="mysql", user="user", passwd="password", db="db")
  File "/home/airflow/.local/lib/python3.7/site-packages/MySQLdb/__init__.py", line 123, in Connect
    return Connection(*args, **kwargs)
  File "/home/airflow/.local/lib/python3.7/site-packages/MySQLdb/connections.py", line 185, in __init__
    super().__init__(*args, **kwargs2)
MySQLdb.OperationalError: (2003, "Can't connect to MySQL server on 'mysql:3306' (113)")
[2022-08-23 17:34:32,436] {taskinstance.py:1420} INFO - Marking task as UP_FOR_RETRY. dag_id=raizen_lab_01, task_id=conecta_no_mysql, execution_date=20220114T100000, start_date=20220823T173429, end_date=20220823T173432
[2022-08-23 17:34:32,474] {standard_task_runner.py:97} ERROR - Failed to execute job 8595 for task conecta_no_mysql ((2003, "Can't connect to MySQL server on 'mysql:3306' (113)"); 172)
[2022-08-23 17:34:32,509] {local_task_job.py:156} INFO - Task exited with return code 1
[2022-08-23 17:34:32,562] {local_task_job.py:273} INFO - 0 downstream tasks scheduled from follow-on schedule check
